[32m2024-10-26 02:03:55 +0800[0m - dagster - [34mDEBUG[0m - ppa_migration_pipeline - b4011e59-9e08-4e58-91d5-4836c8ef0121 - 178438 - LOGS_CAPTURED - Started capturing logs in process (pid: 178438).
[32m2024-10-26 02:03:55 +0800[0m - dagster - [34mDEBUG[0m - ppa_migration_pipeline - b4011e59-9e08-4e58-91d5-4836c8ef0121 - 178438 - insert_merge_asnaf_data - STEP_START - Started execution of step "insert_merge_asnaf_data".
[32m2024-10-26 02:03:55 +0800[0m - dagster - [34mWARNING[0m - ppa_migration_pipeline - b4011e59-9e08-4e58-91d5-4836c8ef0121 - insert_merge_asnaf_data - No previously stored outputs found for source StepOutputHandle(step_key='transform_asnaf_data', output_name='result', mapping_key=None). This is either because you are using an IO Manager that does not depend on run ID, or because all the previous runs have skipped the output in conditional execution.
[32m2024-10-26 02:03:55 +0800[0m - dagster - [34mERROR[0m - [31mppa_migration_pipeline - b4011e59-9e08-4e58-91d5-4836c8ef0121 - 178438 - insert_merge_asnaf_data - STEP_FAILURE - Execution of step "insert_merge_asnaf_data" failed.

dagster._core.errors.DagsterInvariantViolationError: Attempting to access run_id, but it was not provided when constructing the OutputContext

Stack Trace:
  File "/home/mnshuhailey/dev/dev-env/lib/python3.11/site-packages/dagster/_core/execution/plan/execute_plan.py", line 282, in dagster_event_sequence_for_step
    for step_event in check.generator(step_events):
  File "/home/mnshuhailey/dev/dev-env/lib/python3.11/site-packages/dagster/_core/execution/plan/execute_step.py", line 460, in core_dagster_event_sequence_for_step
    for event_or_input_value in step_input.source.load_input_object(
  File "/home/mnshuhailey/dev/dev-env/lib/python3.11/site-packages/dagster/_core/execution/plan/inputs.py", line 477, in load_input_object
    yield from _load_input_with_input_manager(input_manager, load_input_context)
  File "/home/mnshuhailey/dev/dev-env/lib/python3.11/site-packages/dagster/_core/execution/plan/inputs.py", line 804, in _load_input_with_input_manager
    value = input_manager.load_input(context)
            ^^^^^^^^^^^^^^^^^^^^^^^^^^^^^^^^^
  File "/home/mnshuhailey/dev/dev-env/lib/python3.11/site-packages/dagster/_core/storage/upath_io_manager.py", line 404, in load_input
    path = self._get_path(context)
           ^^^^^^^^^^^^^^^^^^^^^^^
  File "/home/mnshuhailey/dev/dev-env/lib/python3.11/site-packages/dagster/_core/storage/upath_io_manager.py", line 198, in _get_path
    path = self._get_path_without_extension(context)
           ^^^^^^^^^^^^^^^^^^^^^^^^^^^^^^^^^^^^^^^^^
  File "/home/mnshuhailey/dev/dev-env/lib/python3.11/site-packages/dagster/_core/storage/upath_io_manager.py", line 164, in _get_path_without_extension
    context_path = self.get_op_output_relative_path(context)
                   ^^^^^^^^^^^^^^^^^^^^^^^^^^^^^^^^^^^^^^^^^
  File "/home/mnshuhailey/dev/dev-env/lib/python3.11/site-packages/dagster/_core/storage/upath_io_manager.py", line 177, in get_op_output_relative_path
    return UPath(*context.get_identifier())
                  ^^^^^^^^^^^^^^^^^^^^^^^^
  File "/home/mnshuhailey/dev/dev-env/lib/python3.11/site-packages/dagster/_core/execution/context/input.py", line 441, in get_identifier
    return self.upstream_output.get_identifier()
           ^^^^^^^^^^^^^^^^^^^^^^^^^^^^^^^^^^^^^
  File "/home/mnshuhailey/dev/dev-env/lib/python3.11/site-packages/dagster/_core/execution/context/output.py", line 589, in get_identifier
    run_id = self.run_id
             ^^^^^^^^^^^
  File "/home/mnshuhailey/dev/dev-env/lib/python3.11/site-packages/dagster/_core/execution/context/output.py", line 217, in run_id
    raise DagsterInvariantViolationError(
[0m
