[32m2024-10-26 02:20:28 +0800[0m - dagster - [34mDEBUG[0m - ppa_migration_pipeline - be717c41-4a06-4880-921b-cfc7fc77b7f6 - 220030 - LOGS_CAPTURED - Started capturing logs in process (pid: 220030).
[32m2024-10-26 02:20:28 +0800[0m - dagster - [34mDEBUG[0m - ppa_migration_pipeline - be717c41-4a06-4880-921b-cfc7fc77b7f6 - 220030 - transform_household_data - STEP_START - Started execution of step "transform_household_data".
[32m2024-10-26 02:20:28 +0800[0m - dagster - [34mINFO[0m - ppa_migration_pipeline - be717c41-4a06-4880-921b-cfc7fc77b7f6 - transform_household_data - Reading data from PostgreSQL.
[32m2024-10-26 02:20:35 +0800[0m - dagster - [34mERROR[0m - [31mppa_migration_pipeline - be717c41-4a06-4880-921b-cfc7fc77b7f6 - 220030 - transform_household_data - STEP_FAILURE - Execution of step "transform_household_data" failed.

dagster._core.errors.DagsterExecutionInterruptedError

Stack Trace:
  File "/home/mnshuhailey/dev/dev-env/lib/python3.11/site-packages/dagster/_core/execution/plan/execute_plan.py", line 282, in dagster_event_sequence_for_step
    for step_event in check.generator(step_events):
  File "/home/mnshuhailey/dev/dev-env/lib/python3.11/site-packages/dagster/_core/execution/plan/execute_step.py", line 494, in core_dagster_event_sequence_for_step
    for user_event in _step_output_error_checked_user_event_sequence(
  File "/home/mnshuhailey/dev/dev-env/lib/python3.11/site-packages/dagster/_core/execution/plan/execute_step.py", line 183, in _step_output_error_checked_user_event_sequence
    for user_event in user_event_sequence:
  File "/home/mnshuhailey/dev/dev-env/lib/python3.11/site-packages/dagster/_core/execution/plan/execute_step.py", line 88, in _process_asset_results_to_events
    for user_event in user_event_sequence:
  File "/home/mnshuhailey/dev/dev-env/lib/python3.11/site-packages/dagster/_core/execution/plan/compute.py", line 198, in execute_core_compute
    for step_output in _yield_compute_results(step_context, inputs, compute_fn, compute_context):
  File "/home/mnshuhailey/dev/dev-env/lib/python3.11/site-packages/dagster/_core/execution/plan/compute.py", line 167, in _yield_compute_results
    for event in iterate_with_context(
  File "/home/mnshuhailey/dev/dev-env/lib/python3.11/site-packages/dagster/_utils/__init__.py", line 473, in iterate_with_context
    next_output = next(iterator)
                  ^^^^^^^^^^^^^^
  File "/home/mnshuhailey/dev/dev-env/lib/python3.11/site-packages/dagster/_core/execution/plan/compute_generator.py", line 141, in _coerce_op_compute_fn_to_iterator
    result = invoke_compute_fn(
             ^^^^^^^^^^^^^^^^^^
  File "/home/mnshuhailey/dev/dev-env/lib/python3.11/site-packages/dagster/_core/execution/plan/compute_generator.py", line 129, in invoke_compute_fn
    return fn(context, **args_to_pass) if context_arg_provided else fn(**args_to_pass)
           ^^^^^^^^^^^^^^^^^^^^^^^^^^^
  File "/home/mnshuhailey/dev/ppa-dagster/ppa_migration/ops/transform_household_data.py", line 22, in transform_household_data
    cursor_pg.execute(fetch_data_query)
  File "/usr/lib/python3.11/encodings/utf_8.py", line 15, in decode
    def decode(input, errors='strict'):
    
  File "/home/mnshuhailey/dev/dev-env/lib/python3.11/site-packages/dagster/_utils/interrupts.py", line 82, in _new_signal_handler
    raise error_cls()
[0m
